Workbook

Sheet Apoio
B2: Centros de Custo | C2: Desc. Centro de Custo | D2: Gestor | F2: Comercialização | G2: Gestão | H2: Geração | J2: Filial | K2: Nome Reduzido | L2: Cluster
B3: C100 | C3: Diretoria | D3: Fernanda Barbosa | J3: ECEL - ELÉTRON COMERCIALIZADORA DE ENERGIA S.A. | K3: ECEL COMERCIALIZADORA | L3: COMERCIALIZADORA | M3: ECEL - ELETRON COMERCIALI
B4: C101 | C4: Comercial | D4: João Lins | J4: MERCURIA COMERCIALIZADORA DE ENERGIA DO BRASIL LTDA | K4: MERCURIA COMERCIALIZADORA | L4: COMERCIALIZADORA | M4: MERCURIA COMERCIALIZADORA
B5: C102 | C5: Jurídico | D5: Cesar Souza | J5: ELETRON POWER GERACAO E COMERCIALIZADORA DE ENERGIA S.A. | K5: ELETRON POWER GERACAO | L5: ELETRON POWER GERACAO | M5: ELETRON POWER GERACAO E C
B6: C103 | C6: Marketing | D6: Mayra Souza | J6: UFV IBIMIRIM 1 GERACAO DE ENERGIA ELETRICA LTDA | K6: UFV IBIMIRIM 1 | L6: IBIMIRINS | M6: UFV IBIMIRIM 1 GERACAO DE
B7: C104 | C7: TI | D7: Marcelo Bronzatti | J7: UFV IBIMIRIM 2 GERACAO DE ENERGIA ELETRICA LTDA | K7: UFV IBIMIRIM 2 | L7: IBIMIRINS | M7: UFV IBIMIRIM 2 GERACAO DE
B8: C105 | C8: Estrutura Corporativo | D8: Rafael Silva | J8: UFV IBIMIRIM 3 GERACAO DE ENERGIA ELETRICA LTDA | K8: UFV IBIMIRIM 3 | L8: IBIMIRINS | M8: UFV IBIMIRIM 3 GERACAO DE
B9: C106 | C9: Gente e Gestão | D9: Emanuelli Colvara | J9: UFV IBIMIRIM 4 GERACAO DE ENERGIA ELETRICA LTDA | K9: UFV IBIMIRIM 4 | L9: IBIMIRINS | M9: UFV IBIMIRIM 4 GERACAO DE
B10: C107 | C10: Tesouraria | D10: Ruan Pereira | J10: UFV IBIMIRIM 5 GERACAO DE ENERGIA ELETRICA LTDA | K10: UFV IBIMIRIM 5 | L10: IBIMIRINS | M10: UFV IBIMIRIM 5 GERACAO DE
B11: C108 | C11: Controladoria | D11: Ray Salvador | J11: UFV IBIMIRIM 6 GERACAO DE ENERGIA ELETRICA LTDA | K11: UFV IBIMIRIM 6 | L11: IBIMIRINS | M11: UFV IBIMIRIM 6 GERACAO DE
B12: C109 | C12: Fiscal | D12: Carlos Augusto Brito | J12: UFV IBIMIRIM 7 GERACAO DE ENERGIA ELETRICA LTDA | K12: UFV IBIMIRIM 7 | L12: IBIMIRINS | M12: UFV IBIMIRIM 7 GERACAO DE
B13: C121 | C13: Cobrança Ecel | D13: Ruan Pereira | J13: UFV IBIMIRIM 8 GERACAO DE ENERGIA ELETRICA LTDA | K13: UFV IBIMIRIM 8 | L13: IBIMIRINS | M13: UFV IBIMIRIM 8 GERACAO DE
B14: C200 | C14: Trading | D14: Fernanda Barbosa | J14: UFV IBIMIRIM 9 GERACAO DE ENERGIA ELETRICA LTDA | K14: UFV IBIMIRIM 9 | L14: IBIMIRINS | M14: UFV IBIMIRIM 9 GERACAO DE
... B21: C600 | C21: Recuperação Judicial (RJ) | D21: Cesar Souza | J21: NOVA RIACHO PARTICIPACOES S.A | K21: NOVA RIACHO PARTICIPACOES | L21: RIACHO | M21: NOVA RIACHO PARTICIPACOES
J22: ELETRON SERVIÇOS LTDA | K22: ELETRON SERVICOS | L22: ELETRON SERVICOS | M22: ELETRON SERVICOS LTDA
J23: ELETRON POWER GD I S.A. | K23: ELETRON POWER GD I | L23: ELETRON POWER GD I | M23: ELETRON POWER GD I S.A.
J24: SPE SE IBIMIRIM ENERGIA LTDA | K24: SPE SE IBIMIRIM | L24: IBIMIRINS | M24: SPE SE IBIMIRIM ENERGIA L
J25: UFV TAPAJOS 1 ENERGIA LTDA | K25: UFV TAPAJOS 1 | L25: GDs | M25: UFV TAPAJOS 1 ENERGIA LTD
J26: UFV TAPAJOS 2 ENERGIA LTDA | K26: UFV TAPAJOS 2 | L26: GDs | M26: UFV TAPAJOS 2 ENERGIA LTD
J27: UFV TAPAJOS 3 ENERGIA LTDA | K27: UFV TAPAJOS 3 | L27: GDs | M27: UFV TAPAJOS 3 ENERGIA LTD
J28: UFV TAPAJOS 4 ENERGIA LTDA | K28: UFV TAPAJOS 4 | L28: GDs | M28: UFV TAPAJOS 4 ENERGIA LTD
J29: UFV TAPAJOS 5 ENERGIA LTDA | K29: UFV TAPAJOS 5 | L29: GDs | M29: UFV TAPAJOS 5 ENERGIA LTD
J30: UFV ENERCRED PE 1 ENERGIA LTDA | K30: UFV ENERCRED PE 1 | L30: GDs | M30: UFV ENERCRED PE 1 ENERGIA
J31: UFV PROPRIA 1 ENERGIA LTDA | K31: UFV PROPRIA | L31: GDs | M31: UFV PROPRIA 1 ENERGIA LTD
J32: UFV PRESIDENTE 1 ENERGIA LTDA | K32: UFV PRESIDENTE 1 | L32: GDs | M32: UFV PRESIDENTE 1 ENERGIA
J33: UFV PRESIDENTE 2 ENERGIA LTDA | K33: UFV PRESIDENTE 2 | L33: GDs | M33: UFV PRESIDENTE 2 ENERGIA
... J81: UFV PAJEU III GERACAO DE ENERGIA SPE LTDA | K81: UFV PAJEU III | L81: GDs | M81: UFV PAJEU III GERACAO DE

Sheet De x Para DRE
B2: Código da conta | C2: Nome da conta | D2: De-Para Balanço IG | E2: DE-Para DRE IG | J2: Agrupamento
B3: 3110100101 | C3: VENDA DE ENERGIA ELÉTRICA | D3: 2.4 Lucros (Prejuízos) Acumulados | E3: 4.1 Receita Bruta Venda de Energia | J3: 3.2 Depreciação/Amortização
B4: 3110100102 | C4: RECEITA C/ NOTAS DE DEBITOS - TUSD E RETUSD | D4: 2.4 Lucros (Prejuízos) Acumulados | E4: 4.1 Receita Bruta Venda de Energia | J4: 3.2 Despesas financeiras
B5: 3110100103 | C5: RECEITA DE LIQUIDAÇÃO FINANCEIRA CCEE | D5: 2.4 Lucros (Prejuízos) Acumulados | E5: 4.1 (+) Liquidações CCEE Receber | J5: 3.2 Project Finance
B6: 3110100104 | C6: RECEITA COM VENDA DE I-REC | D6: 2.4 Lucros (Prejuízos) Acumulados | E6: 4.1 Receita Bruta Venda de Energia | J6: 3.2 Receitas financeiras
B7: 3110100105 | C7: RECEITA C/ NDS TAXAS CCEE VAREJISTAS | D7: 2.4 Lucros (Prejuízos) Acumulados | E7: 4.1 Receita Bruta Venda de Energia | J7: 3.1 G&A
B8: 3110200101 | C8: VENDA SERVIÇO GESTÃO DE ENERGIA | D8: 2.4 Lucros (Prejuízos) Acumulados | E8: 4.1 Receita Bruta sobre Serviços | J8: 3.1 Despesas com pessoal
B9: 3110200102 | C9: VENDA SERVIÇO DE ENERGIA SOLAR | D9: 2.4 Lucros (Prejuízos) Acumulados | E9: 4.1 Receita Bruta sobre Geração | J9: 3.3 TUSD
B10: 3110200103 | C10: VENDA SERVIÇO GESTÃO CONSUMIDORES VAREJO | D10: 2.4 Lucros (Prejuízos) Acumulados | E10: 4.1 Receita Bruta sobre Serviços | J10: 3.4 O&M
B11: 3110200104 | C11: SERVIÇO UP FRONT MKT CONSUMIDORES VAREJO | D11: 2.4 Lucros (Prejuízos) Acumulados | E11: 4.1 Receita Bruta sobre Serviços
B12: 3110200105 | C12: RECEITA GERAÇÃO DE ENERGIA COMPARTILHADA | D12: 2.4 Lucros (Prejuízos) Acumulados | E12: 4.1 Receita Bruta Venda de Energia
B13: 3110300101 | C13: RECEITA ALUGUEL IMÓVEIS | D13: 2.4 Lucros (Prejuízos) Acumulados | E13: 4.1 Receita Bruta sobre Geração
B14: 3110400101 | C14: PROVISÃO VENDA DE ENERGIA - CONTRATOS FUTUROS | D14: 2.4 Lucros (Prejuízos) Acumulados | E14: 4.1 Provisão venda de Energia - Trading
B15: 3110400102 | C15: REVERSÃO PROV. VENDA DE ENERGIA - CONTRATOS FUTUROS | D15: 2.4 Lucros (Prejuízos) Acumulados | E15: 4.1 Reversão Provisão venda de Energia - Trading
B16: 3120100101 | C16: DEV E ANULAÇÃO DE VENDAS | D16: 2.4 Lucros (Prejuízos) Acumulados | E16: 4.1 (-) Deduções
B17: 3120100102 | C17: ABATIMENTOS CONCEDIDOS | D17: 2.4 Lucros (Prejuízos) Acumulados | E17: 4.1 (-) Deduções
B18: 3120100103 | C18: DESCONTOS CONCEDIDOS | D18: 2.4 Lucros (Prejuízos) Acumulados | E18: 4.1 (-) Deduções
B19: 3120100201 | C19: (-) IPI | D19: 2.4 Lucros (Prejuízos) Acumulados | E19: 4.1 (-) Deduções
B20: 3120100202 | C20: (-) PIS | D20: 2.4 Lucros (Prejuízos) Acumulados | E20: 4.1 (-) Deduções
B21: 3120100203 | C21: (-) COFINS | D21: 2.4 Lucros (Prejuízos) Acumulados | E21: 4.1 (-) Deduções
B22: 3120100204 | C22: (-) ICMS | D22: 2.4 Lucros (Prejuízos) Acumulados | E22: 4.1 (-) Deduções
... B210: 5210100203 | C210: REVERSÃO DE PROVISÃO CSLL DIFERIDO | D210: 2.4 Lucros (Prejuízos) Acumulados | E210: 5.1 IR e CSLL Diferido

Sheet Resumo
B2: CENTRO DE CUSTO | C2: TODOS
C3: G&A | XFD3: C104
B4: Filial | C4: Orçado 2026 | D4: Previsto 2026 | E4: Orçado 2027 | F4: Status | XFD4: C202
B5: TOTAL | C5: =SUM(C6:C84) -> 1848174.3 | D5: =SUM(D6:D84) -> 1764198 | E5: =SUM(E6:E84) -> 1772362 | XFD5: TODOS
B6: ECEL COMERCIALIZADORA | C6: =IF($C$2="TODOS",SUMIFS('Orçamento 2027 - G&A'!$W:$W,'Orçamento 2027 - G&A'!$B:$B,Resumo!$B6),SUMIFS('Orçamento 2027 - G&A'!$W:$W,'Orçamento 2027 - G&A'!$B:$B,Resumo!$B6,'Orçamento 2027 - G&A'!$D:$D,Resumo!$C$2)) -> 1848174.3 | D6: =IF($C$2="TODOS",SUMIFS('Orçamento 2027 - G&A'!$AK:$AK,'Orçamento 2027 - G&A'!$B:$B,Resumo!$B6),SUMIFS('Orçamento 2027 - G&A'!$AK:$AK,'Orçamento 2027 - G&A'!$B:$B,Resumo!$B6,'Orçamento 2027 - G&A'!$D:$D,Resumo!$C$2)) -> 1764198 | E6: =IF($C$2="TODOS",SUMIFS('Orçamento 2027 - G&A'!$AX:$AX,'Orçamento 2027 - G&A'!$B:$B,Resumo!$B6),SUMIFS('Orçamento 2027 - G&A'!$AX:$AX,'Orçamento 2027 - G&A'!$B:$B,Resumo!$B6,'Orçamento 2027 - G&A'!$D:$D,Resumo!$C$2)) -> 1772362 | F6: =IF(AND(E6=0,D6<>0),"PENDENTE","OK") -> OK
B7: MERCURIA COMERCIALIZADORA | C7: =IF($C$2="TODOS",SUMIFS('Orçamento 2027 - G&A'!$W:$W,'Orçamento 2027 - G&A'!$B:$B,Resumo!$B7),SUMIFS('Orçamento 2027 - G&A'!$W:$W,'Orçamento 2027 - G&A'!$B:$B,Resumo!$B7,'Orçamento 2027 - G&A'!$D:$D,Resumo!$C$2)) -> 0 | D7: =IF($C$2="TODOS",SUMIFS('Orçamento 2027 - G&A'!$AK:$AK,'Orçamento 2027 - G&A'!$B:$B,Resumo!$B7),SUMIFS('Orçamento 2027 - G&A'!$AK:$AK,'Orçamento 2027 - G&A'!$B:$B,Resumo!$B7,'Orçamento 2027 - G&A'!$D:$D,Resumo!$C$2)) -> 0 | E7: =IF($C$2="TODOS",SUMIFS('Orçamento 2027 - G&A'!$AX:$AX,'Orçamento 2027 - G&A'!$B:$B,Resumo!$B7),SUMIFS('Orçamento 2027 - G&A'!$AX:$AX,'Orçamento 2027 - G&A'!$B:$B,Resumo!$B7,'Orçamento 2027 - G&A'!$D:$D,Resumo!$C$2)) -> 0 | F7: =IF(AND(E7=0,D7<>0),"PENDENTE","OK") -> OK
B8: ELETRON POWER GERACAO | C8: =IF($C$2="TODOS",SUMIFS('Orçamento 2027 - G&A'!$W:$W,'Orçamento 2027 - G&A'!$B:$B,Resumo!$B8),SUMIFS('Orçamento 2027 - G&A'!$W:$W,'Orçamento 2027 - G&A'!$B:$B,Resumo!$B8,'Orçamento 2027 - G&A'!$D:$D,Resumo!$C$2)) -> 0 | D8: =IF($C$2="TODOS",SUMIFS('Orçamento 2027 - G&A'!$AK:$AK,'Orçamento 2027 - G&A'!$B:$B,Resumo!$B8),SUMIFS('Orçamento 2027 - G&A'!$AK:$AK,'Orçamento 2027 - G&A'!$B:$B,Resumo!$B8,'Orçamento 2027 - G&A'!$D:$D,Resumo!$C$2)) -> 0 | E8: =IF($C$2="TODOS",SUMIFS('Orçamento 2027 - G&A'!$AX:$AX,'Orçamento 2027 - G&A'!$B:$B,Resumo!$B8),SUMIFS('Orçamento 2027 - G&A'!$AX:$AX,'Orçamento 2027 - G&A'!$B:$B,Resumo!$B8,'Orçamento 2027 - G&A'!$D:$D,Resumo!$C$2)) -> 0 | F8: =IF(AND(E8=0,D8<>0),"PENDENTE","OK") -> OK
B9: UFV IBIMIRIM 1 | C9: =IF($C$2="TODOS",SUMIFS('Orçamento 2027 - G&A'!$W:$W,'Orçamento 2027 - G&A'!$B:$B,Resumo!$B9),SUMIFS('Orçamento 2027 - G&A'!$W:$W,'Orçamento 2027 - G&A'!$B:$B,Resumo!$B9,'Orçamento 2027 - G&A'!$D:$D,Resumo!$C$2)) -> 0 | D9: =IF($C$2="TODOS",SUMIFS('Orçamento 2027 - G&A'!$AK:$AK,'Orçamento 2027 - G&A'!$B:$B,Resumo!$B9),SUMIFS('Orçamento 2027 - G&A'!$AK:$AK,'Orçamento 2027 - G&A'!$B:$B,Resumo!$B9,'Orçamento 2027 - G&A'!$D:$D,Resumo!$C$2)) -> 0 | E9: =IF($C$2="TODOS",SUMIFS('Orçamento 2027 - G&A'!$AX:$AX,'Orçamento 2027 - G&A'!$B:$B,Resumo!$B9),SUMIFS('Orçamento 2027 - G&A'!$AX:$AX,'Orçamento 2027 - G&A'!$B:$B,Resumo!$B9,'Orçamento 2027 - G&A'!$D:$D,Resumo!$C$2)) -> 0 | F9: =IF(AND(E9=0,D9<>0),"PENDENTE","OK") -> OK
B10: UFV IBIMIRIM 2 | C10: =IF($C$2="TODOS",SUMIFS('Orçamento 2027 - G&A'!$W:$W,'Orçamento 2027 - G&A'!$B:$B,Resumo!$B10),SUMIFS('Orçamento 2027 - G&A'!$W:$W,'Orçamento 2027 - G&A'!$B:$B,Resumo!$B10,'Orçamento 2027 - G&A'!$D:$D,Resumo!$C$2)) -> 0 | D10: =IF($C$2="TODOS",SUMIFS('Orçamento 2027 - G&A'!$AK:$AK,'Orçamento 2027 - G&A'!$B:$B,Resumo!$B10),SUMIFS('Orçamento 2027 - G&A'!$AK:$AK,'Orçamento 2027 - G&A'!$B:$B,Resumo!$B10,'Orçamento 2027 - G&A'!$D:$D,Resumo!$C$2)) -> 0 | E10: =IF($C$2="TODOS",SUMIFS('Orçamento 2027 - G&A'!$AX:$AX,'Orçamento 2027 - G&A'!$B:$B,Resumo!$B10),SUMIFS('Orçamento 2027 - G&A'!$AX:$AX,'Orçamento 2027 - G&A'!$B:$B,Resumo!$B10,'Orçamento 2027 - G&A'!$D:$D,Resumo!$C$2)) -> 0 | F10: =IF(AND(E10=0,D10<>0),"PENDENTE","OK") -> OK
B11: UFV IBIMIRIM 3 | C11: =IF($C$2="TODOS",SUMIFS('Orçamento 2027 - G&A'!$W:$W,'Orçamento 2027 - G&A'!$B:$B,Resumo!$B11),SUMIFS('Orçamento 2027 - G&A'!$W:$W,'Orçamento 2027 - G&A'!$B:$B,Resumo!$B11,'Orçamento 2027 - G&A'!$D:$D,Resumo!$C$2)) -> 0 | D11: =IF($C$2="TODOS",SUMIFS('Orçamento 2027 - G&A'!$AK:$AK,'Orçamento 2027 - G&A'!$B:$B,Resumo!$B11),SUMIFS('Orçamento 2027 - G&A'!$AK:$AK,'Orçamento 2027 - G&A'!$B:$B,Resumo!$B11,'Orçamento 2027 - G&A'!$D:$D,Resumo!$C$2)) -> 0 | E11: =IF($C$2="TODOS",SUMIFS('Orçamento 2027 - G&A'!$AX:$AX,'Orçamento 2027 - G&A'!$B:$B,Resumo!$B11),SUMIFS('Orçamento 2027 - G&A'!$AX:$AX,'Orçamento 2027 - G&A'!$B:$B,Resumo!$B11,'Orçamento 2027 - G&A'!$D:$D,Resumo!$C$2)) -> 0 | F11: =IF(AND(E11=0,D11<>0),"PENDENTE","OK") -> OK
B12: UFV IBIMIRIM 4 | C12: =IF($C$2="TODOS",SUMIFS('Orçamento 2027 - G&A'!$W:$W,'Orçamento 2027 - G&A'!$B:$B,Resumo!$B12),SUMIFS('Orçamento 2027 - G&A'!$W:$W,'Orçamento 2027 - G&A'!$B:$B,Resumo!$B12,'Orçamento 2027 - G&A'!$D:$D,Resumo!$C$2)) -> 0 | D12: =IF($C$2="TODOS",SUMIFS('Orçamento 2027 - G&A'!$AK:$AK,'Orçamento 2027 - G&A'!$B:$B,Resumo!$B12),SUMIFS('Orçamento 2027 - G&A'!$AK:$AK,'Orçamento 2027 - G&A'!$B:$B,Resumo!$B12,'Orçamento 2027 - G&A'!$D:$D,Resumo!$C$2)) -> 0 | E12: =IF($C$2="TODOS",SUMIFS('Orçamento 2027 - G&A'!$AX:$AX,'Orçamento 2027 - G&A'!$B:$B,Resumo!$B12),SUMIFS('Orçamento 2027 - G&A'!$AX:$AX,'Orçamento 2027 - G&A'!$B:$B,Resumo!$B12,'Orçamento 2027 - G&A'!$D:$D,Resumo!$C$2)) -> 0 | F12: =IF(AND(E12=0,D12<>0),"PENDENTE","OK") -> OK
B13: UFV IBIMIRIM 5 | C13: =IF($C$2="TODOS",SUMIFS('Orçamento 2027 - G&A'!$W:$W,'Orçamento 2027 - G&A'!$B:$B,Resumo!$B13),SUMIFS('Orçamento 2027 - G&A'!$W:$W,'Orçamento 2027 - G&A'!$B:$B,Resumo!$B13,'Orçamento 2027 - G&A'!$D:$D,Resumo!$C$2)) -> 0 | D13: =IF($C$2="TODOS",SUMIFS('Orçamento 2027 - G&A'!$AK:$AK,'Orçamento 2027 - G&A'!$B:$B,Resumo!$B13),SUMIFS('Orçamento 2027 - G&A'!$AK:$AK,'Orçamento 2027 - G&A'!$B:$B,Resumo!$B13,'Orçamento 2027 - G&A'!$D:$D,Resumo!$C$2)) -> 0 | E13: =IF($C$2="TODOS",SUMIFS('Orçamento 2027 - G&A'!$AX:$AX,'Orçamento 2027 - G&A'!$B:$B,Resumo!$B13),SUMIFS('Orçamento 2027 - G&A'!$AX:$AX,'Orçamento 2027 - G&A'!$B:$B,Resumo!$B13,'Orçamento 2027 - G&A'!$D:$D,Resumo!$C$2)) -> 0 | F13: =IF(AND(E13=0,D13<>0),"PENDENTE","OK") -> OK
B14: UFV IBIMIRIM 6 | C14: =IF($C$2="TODOS",SUMIFS('Orçamento 2027 - G&A'!$W:$W,'Orçamento 2027 - G&A'!$B:$B,Resumo!$B14),SUMIFS('Orçamento 2027 - G&A'!$W:$W,'Orçamento 2027 - G&A'!$B:$B,Resumo!$B14,'Orçamento 2027 - G&A'!$D:$D,Resumo!$C$2)) -> 0 | D14: =IF($C$2="TODOS",SUMIFS('Orçamento 2027 - G&A'!$AK:$AK,'Orçamento 2027 - G&A'!$B:$B,Resumo!$B14),SUMIFS('Orçamento 2027 - G&A'!$AK:$AK,'Orçamento 2027 - G&A'!$B:$B,Resumo!$B14,'Orçamento 2027 - G&A'!$D:$D,Resumo!$C$2)) -> 0 | E14: =IF($C$2="TODOS",SUMIFS('Orçamento 2027 - G&A'!$AX:$AX,'Orçamento 2027 - G&A'!$B:$B,Resumo!$B14),SUMIFS('Orçamento 2027 - G&A'!$AX:$AX,'Orçamento 2027 - G&A'!$B:$B,Resumo!$B14,'Orçamento 2027 - G&A'!$D:$D,Resumo!$C$2)) -> 0 | F14: =IF(AND(E14=0,D14<>0),"PENDENTE","OK") -> OK
B15: UFV IBIMIRIM 7 | C15: =IF($C$2="TODOS",SUMIFS('Orçamento 2027 - G&A'!$W:$W,'Orçamento 2027 - G&A'!$B:$B,Resumo!$B15),SUMIFS('Orçamento 2027 - G&A'!$W:$W,'Orçamento 2027 - G&A'!$B:$B,Resumo!$B15,'Orçamento 2027 - G&A'!$D:$D,Resumo!$C$2)) -> 0 | D15: =IF($C$2="TODOS",SUMIFS('Orçamento 2027 - G&A'!$AK:$AK,'Orçamento 2027 - G&A'!$B:$B,Resumo!$B15),SUMIFS('Orçamento 2027 - G&A'!$AK:$AK,'Orçamento 2027 - G&A'!$B:$B,Resumo!$B15,'Orçamento 2027 - G&A'!$D:$D,Resumo!$C$2)) -> 0 | E15: =IF($C$2="TODOS",SUMIFS('Orçamento 2027 - G&A'!$AX:$AX,'Orçamento 2027 - G&A'!$B:$B,Resumo!$B15),SUMIFS('Orçamento 2027 - G&A'!$AX:$AX,'Orçamento 2027 - G&A'!$B:$B,Resumo!$B15,'Orçamento 2027 - G&A'!$D:$D,Resumo!$C$2)) -> 0 | F15: =IF(AND(E15=0,D15<>0),"PENDENTE","OK") -> OK
B16: UFV IBIMIRIM 8 | C16: =IF($C$2="TODOS",SUMIFS('Orçamento 2027 - G&A'!$W:$W,'Orçamento 2027 - G&A'!$B:$B,Resumo!$B16),SUMIFS('Orçamento 2027 - G&A'!$W:$W,'Orçamento 2027 - G&A'!$B:$B,Resumo!$B16,'Orçamento 2027 - G&A'!$D:$D,Resumo!$C$2)) -> 0 | D16: =IF($C$2="TODOS",SUMIFS('Orçamento 2027 - G&A'!$AK:$AK,'Orçamento 2027 - G&A'!$B:$B,Resumo!$B16),SUMIFS('Orçamento 2027 - G&A'!$AK:$AK,'Orçamento 2027 - G&A'!$B:$B,Resumo!$B16,'Orçamento 2027 - G&A'!$D:$D,Resumo!$C$2)) -> 0 | E16: =IF($C$2="TODOS",SUMIFS('Orçamento 2027 - G&A'!$AX:$AX,'Orçamento 2027 - G&A'!$B:$B,Resumo!$B16),SUMIFS('Orçamento 2027 - G&A'!$AX:$AX,'Orçamento 2027 - G&A'!$B:$B,Resumo!$B16,'Orçamento 2027 - G&A'!$D:$D,Resumo!$C$2)) -> 0 | F16: =IF(AND(E16=0,D16<>0),"PENDENTE","OK") -> OK
B17: UFV IBIMIRIM 9 | C17: =IF($C$2="TODOS",SUMIFS('Orçamento 2027 - G&A'!$W:$W,'Orçamento 2027 - G&A'!$B:$B,Resumo!$B17),SUMIFS('Orçamento 2027 - G&A'!$W:$W,'Orçamento 2027 - G&A'!$B:$B,Resumo!$B17,'Orçamento 2027 - G&A'!$D:$D,Resumo!$C$2)) -> 0 | D17: =IF($C$2="TODOS",SUMIFS('Orçamento 2027 - G&A'!$AK:$AK,'Orçamento 2027 - G&A'!$B:$B,Resumo!$B17),SUMIFS('Orçamento 2027 - G&A'!$AK:$AK,'Orçamento 2027 - G&A'!$B:$B,Resumo!$B17,'Orçamento 2027 - G&A'!$D:$D,Resumo!$C$2)) -> 0 | E17: =IF($C$2="TODOS",SUMIFS('Orçamento 2027 - G&A'!$AX:$AX,'Orçamento 2027 - G&A'!$B:$B,Resumo!$B17),SUMIFS('Orçamento 2027 - G&A'!$AX:$AX,'Orçamento 2027 - G&A'!$B:$B,Resumo!$B17,'Orçamento 2027 - G&A'!$D:$D,Resumo!$C$2)) -> 0 | F17: =IF(AND(E17=0,D17<>0),"PENDENTE","OK") -> OK
... B84: UFV PAJEU III | C84: =IF($C$2="TODOS",SUMIFS('Orçamento 2027 - G&A'!$W:$W,'Orçamento 2027 - G&A'!$B:$B,Resumo!$B84),SUMIFS('Orçamento 2027 - G&A'!$W:$W,'Orçamento 2027 - G&A'!$B:$B,Resumo!$B84,'Orçamento 2027 - G&A'!$D:$D,Resumo!$C$2)) -> 0 | D84: =IF($C$2="TODOS",SUMIFS('Orçamento 2027 - G&A'!$AK:$AK,'Orçamento 2027 - G&A'!$B:$B,Resumo!$B84),SUMIFS('Orçamento 2027 - G&A'!$AK:$AK,'Orçamento 2027 - G&A'!$B:$B,Resumo!$B84,'Orçamento 2027 - G&A'!$D:$D,Resumo!$C$2)) -> 0 | E84: =IF($C$2="TODOS",SUMIFS('Orçamento 2027 - G&A'!$AX:$AX,'Orçamento 2027 - G&A'!$B:$B,Resumo!$B84),SUMIFS('Orçamento 2027 - G&A'!$AX:$AX,'Orçamento 2027 - G&A'!$B:$B,Resumo!$B84,'Orçamento 2027 - G&A'!$D:$D,Resumo!$C$2)) -> 0 | F84: =IF(AND(E84=0,D84<>0),"PENDENTE","OK") -> OK

Sheet Orçamento 2027 - G&A
A1: ORÇAMENTO 2027 | PLANEJAMENTO POR CENTRO DE CUSTO
A3: Como usar: filtre Centro de Custo ou Responsável no cabeçalho da tabela, selecione Filial e Conta, preencha os valores mensais em azul e finalize a linha quando a proposta estiver revisada. O histórico será trazido automaticamente após a carga na aba Base Histórico.
A4: Legenda: azul = entrada do gestor | verde = vínculo automático | preto = cálculo
A6: IDENTIFICAÇÃO | K6: ORÇAMENTO 2026 | X6: PROJETADO 2026 | AJ6: HISTÓRICO | AL6: ORÇAMENTO 2027 | ENTRADAS MENSAIS | AX6: TOTAL E VARIAÇÃO | BA6: GESTÃO
A7: Linha | B7: Filial | C7: Cluster | D7: Centro de Custo | E7: Diretoria | F7: Responsável | G7: =IF($H7="","",IFERROR(_xlfn.XLOOKUP(H7,'De x Para DRE'!C:C,'De x Para DRE'!B:B),"")) -> Código da conta | H7: Nome da Conta | I7: Linha DRE | J7: Descrição | K7: Jan | L7: Fev | M7: Mar | N7: Abr | O7: Mai | P7: Jun | Q7: Jul | R7: Ago | S7: Set | T7: Out | U7: Nov | V7: Dez | W7: Orçado 2026 | X7: Jan | Y7: Fev | Z7: Mar | AA7: Abr | AB7: Mai | AC7: Jun | AD7: Jul | AE7: Ago | AF7: Set | AG7: Out | AH7: Nov | AI7: Dez | AJ7: Real 2026 YTD | AK7: Projeção 2026 | AL7: Jan | AM7: Fev | AN7: Mar | AO7: Abr | AP7: Mai | AQ7: Jun | AR7: Jul | AS7: Ago | AT7: Set | AU7: Out | AV7: Nov | AW7: Dez | AX7: Orçado 2027 | AY7: Var. R$ vs 2026 Orç. | AZ7: Var. R$ vs 2026 Proj. | BA7: Justificativa | BB7: Status
A8: =IF(OR($B8="",$D8="",$G8=""),"",ROW()-7) -> 1 | B8: ECEL COMERCIALIZADORA | C8: =IF($B8="","",IFERROR(INDEX(Apoio!$L$3:$L$81,MATCH($B8,Apoio!$K$3:$K$81,0)),"")) -> COMERCIALIZADORA | D8: C104 | E8: =IF($D8="","",IFERROR(INDEX(Apoio!$C$3:$C$81,MATCH($D8,Apoio!$B$3:$B$81,0)),"")) -> TI | F8: =IF($D8="","",IFERROR(INDEX(Apoio!$D$3:$D$81,MATCH($D8,Apoio!$B$3:$B$81,0)),"")) -> Marcelo Bronzatti | G8: =IF($H8="","",IFERROR(_xlfn.XLOOKUP(H8,'De x Para DRE'!C:C,'De x Para DRE'!B:B),"")) -> 5110100702 | H8: SISTEMAS DE GESTÃO ADM/OPERACIONAL | I8: =IF($G8="","",IFERROR(INDEX('De x Para DRE'!$E$3:$E$210,MATCH($G8,'De x Para DRE'!$B$3:$B$210,0)),"")) -> 3.1 G&A | J8: Consultoria SAP - Alfa | K8: 30600 | L8: 30600 | M8: 30600 | N8: 30600 | O8: 30600 | P8: 30600 | W8: =SUM(K8:V8) -> 183600 | X8: 29404.52 | Y8: 30658.45 | Z8: 30658.45 | AA8: 30658.45 | AB8: =25604.15+5054.3 -> 30658.45 | AC8: =2381.25+458.84+22764.06+5054.3 -> 30658.45 | AD8: 0 | AE8: 0 | AG8: 0 | AH8: 0 | AI8: 0 | AJ8: =SUM(X8:AE8) -> 182696.77 | AK8: =SUM(X8:AI8) -> 182696.77 | AL8: 0 | AM8: 0 | AN8: 0 | AO8: 0 | AP8: 0 | AQ8: 0 | AR8: 0 | AS8: 0 | AT8: 0 | AU8: 0 | AV8: 0 | AW8: 0 | AX8: =IF(COUNT($AL8:$AW8)=0,"",SUM($AL8:$AW8)) -> 0 | AY8: =IF($AX8="","",$AX8-IF($W8="",0,$W8)) -> -183600 | AZ8: =IF($AX8="","",$AX8-IF($AK8="",0,$AK8)) -> -182696.77 | BB8: Rascunho
A9: =IF(OR($B9="",$D9="",$G9=""),"",ROW()-7) -> 2 | B9: ECEL COMERCIALIZADORA | C9: =IF($B9="","",IFERROR(INDEX(Apoio!$L$3:$L$81,MATCH($B9,Apoio!$K$3:$K$81,0)),"")) -> COMERCIALIZADORA | D9: C104 | E9: =IF($D9="","",IFERROR(INDEX(Apoio!$C$3:$C$81,MATCH($D9,Apoio!$B$3:$B$81,0)),"")) -> TI | F9: =IF($D9="","",IFERROR(INDEX(Apoio!$D$3:$D$81,MATCH($D9,Apoio!$B$3:$B$81,0)),"")) -> Marcelo Bronzatti | G9: =IF($H9="","",IFERROR(_xlfn.XLOOKUP(H9,'De x Para DRE'!C:C,'De x Para DRE'!B:B),"")) -> 5110100702 | H9: SISTEMAS DE GESTÃO ADM/OPERACIONAL | I9: =IF($G9="","",IFERROR(INDEX('De x Para DRE'!$E$3:$E$210,MATCH($G9,'De x Para DRE'!$B$3:$B$210,0)),"")) -> 3.1 G&A | J9: Consultoria SAP - Ramo | M9: 4000 | N9: 4000 | O9: =4000+2720+3685.13 -> 10405.13 | P9: =4000+2720+3685.13 -> 10405.13 | Q9: =4000+2720+3685.13+16716 -> 27121.13 | R9: =4000+2720+3685.13+16716 -> 27121.13 | S9: =4000+2720+3685.13+16716 -> 27121.13 | T9: =4000+2720+3685.13+16716 -> 27121.13 | U9: =4000+16716 -> 20716 | V9: =4000+16716 -> 20716 | W9: =SUM(K9:V9) -> 178726.78 | X9: =2975.75 -> 2975.75 | Y9: =2975.75 -> 2975.75 | AA9: =5029.16+3202.57+16716 -> 24947.73 | AB9: =3202.57+16716+5029.16 -> 24947.73 | AC9: =3202.57+15251+5029.16 -> 23482.73 | AD9: =15251+5029.16+3202.57 -> 23482.73 | AE9: 23482.73 | AF9: 23482.73 | AG9: 23482.73 | AH9: 23482.73 | AI9: 23482.73 | AJ9: =SUM(X9:AE9) -> 126295.15 | AK9: =SUM(X9:AI9) -> 220226.07 | AL9: 16000 | AM9: 16000 | AN9: 16000 | AO9: 16000 | AP9: 16000 | AQ9: 16000 | AR9: 16000 | AS9: 16000 | AT9: 16000 | AU9: 16000 | AV9: 16000 | AW9: 16000 | AX9: =IF(COUNT($AL9:$AW9)=0,"",SUM($AL9:$AW9)) -> 192000 | AY9: =IF($AX9="","",$AX9-IF($W9="",0,$W9)) -> 13273.22 | AZ9: =IF($AX9="","",$AX9-IF($AK9="",0,$AK9)) -> -28226.07 | BA9: REAJUSTE IGPM | BB9: Rascunho
A10: =IF(OR($B10="",$D10="",$G10=""),"",ROW()-7) -> 3 | B10: ECEL COMERCIALIZADORA | C10: =IF($B10="","",IFERROR(INDEX(Apoio!$L$3:$L$81,MATCH($B10,Apoio!$K$3:$K$81,0)),"")) -> COMERCIALIZADORA | D10: C104 | E10: =IF($D10="","",IFERROR(INDEX(Apoio!$C$3:$C$81,MATCH($D10,Apoio!$B$3:$B$81,0)),"")) -> TI | F10: =IF($D10="","",IFERROR(INDEX(Apoio!$D$3:$D$81,MATCH($D10,Apoio!$B$3:$B$81,0)),"")) -> Marcelo Bronzatti | G10: =IF($H10="","",IFERROR(_xlfn.XLOOKUP(H10,'De x Para DRE'!C:C,'De x Para DRE'!B:B),"")) -> 5110100702 | H10: SISTEMAS DE GESTÃO ADM/OPERACIONAL | I10: =IF($G10="","",IFERROR(INDEX('De x Para DRE'!$E$3:$E$210,MATCH($G10,'De x Para DRE'!$B$3:$B$210,0)),"")) -> 3.1 G&A | J10: StarSoft - Sistema Folha de Pagamento | K10: 1950 | L10: 1950 | M10: 1950 | N10: 1950 | O10: 1950 | P10: 1950 | Q10: 2047.5 | R10: 2047.5 | S10: 2047.5 | T10: 2047.5 | U10: 2047.5 | V10: 2047.5 | W10: =SUM(K10:V10) -> 23985 | X10: 1950 | Y10: 1950 | Z10: 1950 | AA10: 1950 | AB10: 1950 | AD10: 0 | AE10: 0 | AF10: 0 | AG10: 0 | AH10: 0 | AI10: 0 | AJ10: =SUM(X10:AE10) -> 9750 | AK10: =SUM(X10:AI10) -> 9750 | AL10: 0 | AM10: 0 | AN10: 0 | AO10: 0 | AP10: 0 | AQ10: 0 | AR10: 0 | AS10: 0 | AT10: 0 | AU10: 0 | AV10: 0 | AW10: 0 | AX10: =IF(COUNT($AL10:$AW10)=0,"",SUM($AL10:$AW10)) -> 0 | AY10: =IF($AX10="","",$AX10-IF($W10="",0,$W10)) -> -23985 | AZ10: =IF($AX10="","",$AX10-IF($AK10="",0,$AK10)) -> -9750 | BB10: Rascunho
A11: =IF(OR($B11="",$D11="",$G11=""),"",ROW()-7) -> 4 | B11: ECEL COMERCIALIZADORA | C11: =IF($B11="","",IFERROR(INDEX(Apoio!$L$3:$L$81,MATCH($B11,Apoio!$K$3:$K$81,0)),"")) -> COMERCIALIZADORA | D11: C104 | E11: =IF($D11="","",IFERROR(INDEX(Apoio!$C$3:$C$81,MATCH($D11,Apoio!$B$3:$B$81,0)),"")) -> TI | F11: =IF($D11="","",IFERROR(INDEX(Apoio!$D$3:$D$81,MATCH($D11,Apoio!$B$3:$B$81,0)),"")) -> Marcelo Bronzatti | G11: =IF($H11="","",IFERROR(_xlfn.XLOOKUP(H11,'De x Para DRE'!C:C,'De x Para DRE'!B:B),"")) -> 5110100702 | H11: SISTEMAS DE GESTÃO ADM/OPERACIONAL | I11: =IF($G11="","",IFERROR(INDEX('De x Para DRE'!$E$3:$E$210,MATCH($G11,'De x Para DRE'!$B$3:$B$210,0)),"")) -> 3.1 G&A | J11: TopDesk - Sistema de Chamados TI | K11: 7234 | L11: 7234 | M11: 7234 | N11: 7547.02 | O11: 7547.02 | P11: 7547.02 | Q11: 7547.02 | R11: 7547.02 | S11: 7547.02 | T11: 7547.02 | U11: 7547.02 | V11: 7547.02 | W11: =SUM(K11:V11) -> 89625.18 | X11: 7233.5 | Y11: 7233.5 | Z11: 7233.5 | AA11: 15089.08 | AB11: 7544.54 | AC11: 7544.54 | AD11: 5014.46 | AE11: 5014.46 | AF11: 5014.46 | AG11: 5014.46 | AH11: 5014.46 | AI11: 5014.46 | AJ11: =SUM(X11:AE11) -> 61907.58 | AK11: =SUM(X11:AI11) -> 81965.42 | AL11: 5015 | AM11: 5015 | AN11: 5015 | AO11: 5015 | AP11: 0 | AQ11: 0 | AR11: 0 | AS11: 0 | AT11: 0 | AU11: 0 | AV11: 0 | AW11: 0 | AX11: =IF(COUNT($AL11:$AW11)=0,"",SUM($AL11:$AW11)) -> 20060 | AY11: =IF($AX11="","",$AX11-IF($W11="",0,$W11)) -> -69565.18 | AZ11: =IF($AX11="","",$AX11-IF($AK11="",0,$AK11)) -> -61905.42 | BA11: RESCISÃO EM 31/03/27 | BB11: Rascunho
A12: =IF(OR($B12="",$D12="",$G12=""),"",ROW()-7) -> 5 | B12: ECEL COMERCIALIZADORA | C12: =IF($B12="","",IFERROR(INDEX(Apoio!$L$3:$L$81,MATCH($B12,Apoio!$K$3:$K$81,0)),"")) -> COMERCIALIZADORA | D12: C104 | E12: =IF($D12="","",IFERROR(INDEX(Apoio!$C$3:$C$81,MATCH($D12,Apoio!$B$3:$B$81,0)),"")) -> TI | F12: =IF($D12="","",IFERROR(INDEX(Apoio!$D$3:$D$81,MATCH($D12,Apoio!$B$3:$B$81,0)),"")) -> Marcelo Bronzatti | G12: =IF($H12="","",IFERROR(_xlfn.XLOOKUP(H12,'De x Para DRE'!C:C,'De x Para DRE'!B:B),"")) -> 5110100702 | H12: SISTEMAS DE GESTÃO ADM/OPERACIONAL | I12: =IF($G12="","",IFERROR(INDEX('De x Para DRE'!$E$3:$E$210,MATCH($G12,'De x Para DRE'!$B$3:$B$210,0)),"")) -> 3.1 G&A | J12: SKYOne | K12: 4232 | L12: 4232 | M12: 4232 | N12: =4232+5894 -> 10126 | O12: =4232+5894 -> 10126 | P12: =4232+5894 -> 10126 | Q12: =4443.6+5894 -> 10337.6 | R12: =4443.6+5894 -> 10337.6 | S12: =4443.6+5894 -> 10337.6 | T12: =4443.6+5894 -> 10337.6 | U12: =4443.6+5894 -> 10337.6 | V12: =4443.6+5894 -> 10337.6 | W12: =SUM(K12:V12) -> 105099.6 | X12: 0 | Y12: 8464.42 | Z12: 0 | AA12: 10706.3 | AB12: =3785.4+2688.69+4232.21 -> 10706.3 | AC12: =2688.69+3785.4+2688.69+3785.4+4232.21 -> 17180.39 | AD12: 10706.3 | AE12: 10706.3 | AF12: 10706.3 | AG12: 10706.3 | AH12: 10706.3 | AI12: 10706.3 | AJ12: =SUM(X12:AE12) -> 68470.01 | AK12: =SUM(X12:AI12) -> 111295.21 | AL12: 11000 | AM12: 11000 | AN12: 11500 | AO12: 11500 | AP12: 11500 | AQ12: 11500 | AR12: 11500 | AS12: 11500 | AT12: 11500 | AU12: 11500 | AV12: 11500 | AW12: 11500 | AX12: =IF(COUNT($AL12:$AW12)=0,"",SUM($AL12:$AW12)) -> 137000 | AY12: =IF($AX12="","",$AX12-IF($W12="",0,$W12)) -> 31900.4 | AZ12: =IF($AX12="","",$AX12-IF($AK12="",0,$AK12)) -> 25704.79 | BA12: REAJUSTE IGPM STUDIO SKU - 4500,00 AUTOSKY - 6500,00 | BB12: Rascunho
A13: =IF(OR($B13="",$D13="",$G13=""),"",ROW()-7) -> 6 | B13: ECEL COMERCIALIZADORA | C13: =IF($B13="","",IFERROR(INDEX(Apoio!$L$3:$L$81,MATCH($B13,Apoio!$K$3:$K$81,0)),"")) -> COMERCIALIZADORA | D13: C104 | E13: =IF($D13="","",IFERROR(INDEX(Apoio!$C$3:$C$81,MATCH($D13,Apoio!$B$3:$B$81,0)),"")) -> TI | F13: =IF($D13="","",IFERROR(INDEX(Apoio!$D$3:$D$81,MATCH($D13,Apoio!$B$3:$B$81,0)),"")) -> Marcelo Bronzatti | G13: =IF($H13="","",IFERROR(_xlfn.XLOOKUP(H13,'De x Para DRE'!C:C,'De x Para DRE'!B:B),"")) -> 5110100702 | H13: SISTEMAS DE GESTÃO ADM/OPERACIONAL | I13: =IF($G13="","",IFERROR(INDEX('De x Para DRE'!$E$3:$E$210,MATCH($G13,'De x Para DRE'!$B$3:$B$210,0)),"")) -> 3.1 G&A | J13: ClickSign - Assinatura Documentos | K13: 789 | L13: 789 | M13: 789 | N13: 789 | O13: 789 | P13: 789 | Q13: 828.45 | R13: 828.45 | S13: 828.45 | T13: 828.45 | U13: 828.45 | V13: 828.45 | W13: =SUM(K13:V13) -> 9704.7 | X13: =789+789 -> 1578 | Y13: 789 | Z13: 789 | AA13: 789 | AB13: 789 | AC13: 789 | AD13: 789 | AE13: 795.96 | AF13: 795.96 | AG13: 795.96 | AH13: 795.96 | AI13: 795.96 | AJ13: =SUM(X13:AE13) -> 7107.96 | AK13: =SUM(X13:AI13) -> 10291.8 | AL13: 830 | AM13: 830 | AN13: 830 | AO13: 830 | AP13: 830 | AQ13: 830 | AR13: 830 | AS13: 860 | AT13: 860 | AU13: 860 | AV13: 860 | AW13: 860 | AX13: =IF(COUNT($AL13:$AW13)=0,"",SUM($AL13:$AW13)) -> 10110 | AY13: =IF($AX13="","",$AX13-IF($W13="",0,$W13)) -> 405.3 | AZ13: =IF($AX13="","",$AX13-IF($AK13="",0,$AK13)) -> -181.8 | BB13: Rascunho
A14: =IF(OR($B14="",$D14="",$G14=""),"",ROW()-7) -> 7 | B14: ECEL COMERCIALIZADORA | C14: =IF($B14="","",IFERROR(INDEX(Apoio!$L$3:$L$81,MATCH($B14,Apoio!$K$3:$K$81,0)),"")) -> COMERCIALIZADORA | D14: C104 | E14: =IF($D14="","",IFERROR(INDEX(Apoio!$C$3:$C$81,MATCH($D14,Apoio!$B$3:$B$81,0)),"")) -> TI | F14: =IF($D14="","",IFERROR(INDEX(Apoio!$D$3:$D$81,MATCH($D14,Apoio!$B$3:$B$81,0)),"")) -> Marcelo Bronzatti | G14: =IF($H14="","",IFERROR(_xlfn.XLOOKUP(H14,'De x Para DRE'!C:C,'De x Para DRE'!B:B),"")) -> 5110100702 | H14: SISTEMAS DE GESTÃO ADM/OPERACIONAL | I14: =IF($G14="","",IFERROR(INDEX('De x Para DRE'!$E$3:$E$210,MATCH($G14,'De x Para DRE'!$B$3:$B$210,0)),"")) -> 3.1 G&A | J14: Paradigma - Sistema BackOffice | K14: 36714 | L14: 36714 | M14: 36714 | N14: 36714 | O14: 36714 | P14: 36714 | Q14: 38549.7 | R14: 38549.7 | S14: 38549.7 | T14: 38549.7 | U14: 38549.7 | V14: 38549.7 | W14: =SUM(K14:V14) -> 451582.2 | X14: =1500+10000+25213.83 -> 36713.83 | Y14: =3000+10000+25213.83-1500 -> 36713.83 | Z14: =1500+10000+25213.83 -> 36713.83 | AA14: =1891.02+10000+25213.83+2130.34 -> 39235.19 | AB14: =10000+25213.83+1800+2130.34 -> 39144.17 | AC14: =10000+15877.79+2130.34 -> 28008.13 | AD14: =15877.79+10000+2130.34 -> 28008.13 | AE14: =15877.79+10000+2130.34 -> 28008.13 | AF14: 28008.13 | AG14: 28008.13 | AH14: 28008.13 | AI14: 28008.13 | AJ14: =SUM(X14:AE14) -> 272545.24 | AK14: =SUM(X14:AI14) -> 384577.76 | AL14: 36800 | AM14: 36800 | AN14: 36800 | AO14: 38400 | AP14: 38400 | AQ14: 38400 | AR14: 38400 | AS14: 38400 | AT14: 38400 | AU14: 38400 | AV14: 38400 | AW14: 38400 | AX14: =IF(COUNT($AL14:$AW14)=0,"",SUM($AL14:$AW14)) -> 456000 | AY14: =IF($AX14="","",$AX14-IF($W14="",0,$W14)) -> 4417.8 | AZ14: =IF($AX14="","",$AX14-IF($AK14="",0,$AK14)) -> 71422.24 | BA14: RETORNO DO VALOR RENEG E REAJUSTE IGPM *DEVE SER FEITO AVISO PREVIO EM JAN/27 E MIGRAR PARA BOLETADOR* | BB14: Rascunho
A15: =IF(OR($B15="",$D15="",$G15=""),"",ROW()-7) -> 8 | B15: ECEL COMERCIALIZADORA | C15: =IF($B15="","",IFERROR(INDEX(Apoio!$L$3:$L$81,MATCH($B15,Apoio!$K$3:$K$81,0)),"")) -> COMERCIALIZADORA | D15: C104 | E15: =IF($D15="","",IFERROR(INDEX(Apoio!$C$3:$C$81,MATCH($D15,Apoio!$B$3:$B$81,0)),"")) -> TI | F15: =IF($D15="","",IFERROR(INDEX(Apoio!$D$3:$D$81,MATCH($D15,Apoio!$B$3:$B$81,0)),"")) -> Marcelo Bronzatti | G15: =IF($H15="","",IFERROR(_xlfn.XLOOKUP(H15,'De x Para DRE'!C:C,'De x Para DRE'!B:B),"")) -> 5110100702 | H15: SISTEMAS DE GESTÃO ADM/OPERACIONAL | I15: =IF($G15="","",IFERROR(INDEX('De x Para DRE'!$E$3:$E$210,MATCH($G15,'De x Para DRE'!$B$3:$B$210,0)),"")) -> 3.1 G&A | J15: TeamGuide - Sistema de Gestão de Pessoas | K15: 1705 | L15: 1705 | M15: 1705 | N15: 1705 | O15: 1705 | P15: 1705 | Q15: 1449.25 | R15: 1449.25 | S15: 1449.25 | T15: 1449.25 | U15: 1449.25 | V15: 1449.25 | W15: =SUM(K15:V15) -> 18925.5 | X15: 1272 | Y15: =1188+264 -> 1452 | Z15: =1068 -> 1068 | AA15: =1056+288+72+72 -> 1488 | AB15: =1188+60 -> 1248 | AC15: =1068+60 -> 1128 | AD15: 1092 | AE15: 1116 | AF15: =AE15 -> 1116 | AG15: =AF15 -> 1116 | AH15: =AG15 -> 1116 | AI15: =AH15 -> 1116 | AJ15: =SUM(X15:AE15) -> 9864 | AK15: =SUM(X15:AI15) -> 14328 | AL15: 0 | AM15: 0 | AN15: 0 | AO15: 0 | AP15: 0 | AQ15: 0 | AR15: 0 | AS15: 0 | AT15: 0 | AU15: 0 | AV15: 0 | AW15: 0 | AX15: =IF(COUNT($AL15:$AW15)=0,"",SUM($AL15:$AW15)) -> 0 | AY15: =IF($AX15="","",$AX15-IF($W15="",0,$W15)) -> -18925.5 | AZ15: =IF($AX15="","",$AX15-IF($AK15="",0,$AK15)) -> -14328 | BB15: Rascunho
A16: =IF(OR($B16="",$D16="",$G16=""),"",ROW()-7) -> 9 | B16: ECEL COMERCIALIZADORA | C16: =IF($B16="","",IFERROR(INDEX(Apoio!$L$3:$L$81,MATCH($B16,Apoio!$K$3:$K$81,0)),"")) -> COMERCIALIZADORA | D16: C104 | E16: =IF($D16="","",IFERROR(INDEX(Apoio!$C$3:$C$81,MATCH($D16,Apoio!$B$3:$B$81,0)),"")) -> TI | F16: =IF($D16="","",IFERROR(INDEX(Apoio!$D$3:$D$81,MATCH($D16,Apoio!$B$3:$B$81,0)),"")) -> Marcelo Bronzatti | G16: =IF($H16="","",IFERROR(_xlfn.XLOOKUP(H16,'De x Para DRE'!C:C,'De x Para DRE'!B:B),"")) -> 5110100702 | H16: SISTEMAS DE GESTÃO ADM/OPERACIONAL | I16: =IF($G16="","",IFERROR(INDEX('De x Para DRE'!$E$3:$E$210,MATCH($G16,'De x Para DRE'!$B$3:$B$210,0)),"")) -> 3.1 G&A | J16: Colmeia - Sistema | K16: 1700 | L16: 1700 | M16: 1700 | N16: 2000 | O16: 2000 | P16: 2000 | Q16: 2000 | R16: 2500 | S16: 2500 | T16: 2500 | U16: 2500 | V16: 2500 | W16: =SUM(K16:V16) -> 25600 | X16: 3320.71 | Y16: 1541.21 | Z16: 1840.61 | AA16: 1497.47 | AB16: 2333.88 | AC16: 3053.31 | AD16: =3678.65 -> 3678.65 | AE16: =3267.99 -> 3267.99 | AF16: =AE16 -> 3267.99 | AG16: =AF16 -> 3267.99 | AH16: =AG16 -> 3267.99 | AI16: =AH16 -> 3267.99 | AJ16: =SUM(X16:AE16) -> 20533.83 | AK16: =SUM(X16:AI16) -> 33605.79 | AL16: 5000 | AM16: 5000 | AN16: 5000 | AO16: 5000 | AP16: 6500 | AQ16: 6500 | AR16: 6500 | AS16: 6500 | AT16: 6500 | AU16: 6500 | AV16: 6500 | AW16: 6500 | AX16: =IF(COUNT($AL16:$AW16)=0,"",SUM($AL16:$AW16)) -> 72000 | AY16: =IF($AX16="","",$AX16-IF($W16="",0,$W16)) -> 46400 | AZ16: =IF($AX16="","",$AX16-IF($AK16="",0,$AK16)) -> 38394.21 | BA16: AUMENTO DE VOLUME DE UTILIZAÇÃO PARA DISPAROS E ATENDIMENTO CHATBOT - ENTRADA DO VAREJO - Aumento de valores cambiais da Meta. | BB16: Rascunho
A17: =IF(OR($B17="",$D17="",$G17=""),"",ROW()-7) -> 10 | B17: ECEL COMERCIALIZADORA | C17: =IF($B17="","",IFERROR(INDEX(Apoio!$L$3:$L$81,MATCH($B17,Apoio!$K$3:$K$81,0)),"")) -> COMERCIALIZADORA | D17: C104 | E17: =IF($D17="","",IFERROR(INDEX(Apoio!$C$3:$C$81,MATCH($D17,Apoio!$B$3:$B$81,0)),"")) -> TI | F17: =IF($D17="","",IFERROR(INDEX(Apoio!$D$3:$D$81,MATCH($D17,Apoio!$B$3:$B$81,0)),"")) -> Marcelo Bronzatti | G17: =IF($H17="","",IFERROR(_xlfn.XLOOKUP(H17,'De x Para DRE'!C:C,'De x Para DRE'!B:B),"")) -> 5110100702 | H17: SISTEMAS DE GESTÃO ADM/OPERACIONAL | I17: =IF($G17="","",IFERROR(INDEX('De x Para DRE'!$E$3:$E$210,MATCH($G17,'De x Para DRE'!$B$3:$B$210,0)),"")) -> 3.1 G&A | J17: ARPSist - Sistema | K17: 1380 | L17: 1380 | M17: 1380 | N17: 1380 | O17: 1380 | P17: 1380 | Q17: 1449 | R17: 1449 | S17: 1449 | T17: 1449 | U17: 1449 | V17: 1449 | W17: =SUM(K17:V17) -> 16974 | X17: 1380 | Y17: 1380 | Z17: 1380 | AA17: 1380 | AB17: 1380 | AC17: 1560 | AD17: 1560 | AE17: 1560 | AF17: 1560 | AG17: 1560 | AH17: 1560 | AI17: 1560 | AJ17: =SUM(X17:AE17) -> 11580 | AK17: =SUM(X17:AI17) -> 17820 | AL17: 1300 | AM17: 1300 | AN17: 1300 | AO17: 1300 | AP17: 1300 | AQ17: 1300 | AR17: 1300 | AS17: 1300 | AT17: 1300 | AU17: 1300 | AV17: 1300 | AW17: 1300 | AX17: =IF(COUNT($AL17:$AW17)=0,"",SUM($AL17:$AW17)) -> 15600 | AY17: =IF($AX17="","",$AX17-IF($W17="",0,$W17)) -> -1374 | AZ17: =IF($AX17="","",$AX17-IF($AK17="",0,$AK17)) -> -2220 | BA17: NEGOCIADO REDUÇÃO DE VLR PARA 4HS + 1 ALUGUEL DO MR44 | BB17: Rascunho
A18: =IF(OR($B18="",$D18="",$G18=""),"",ROW()-7) -> 11 | B18: ECEL COMERCIALIZADORA | C18: =IF($B18="","",IFERROR(INDEX(Apoio!$L$3:$L$81,MATCH($B18,Apoio!$K$3:$K$81,0)),"")) -> COMERCIALIZADORA | D18: C104 | E18: =IF($D18="","",IFERROR(INDEX(Apoio!$C$3:$C$81,MATCH($D18,Apoio!$B$3:$B$81,0)),"")) -> TI | F18: =IF($D18="","",IFERROR(INDEX(Apoio!$D$3:$D$81,MATCH($D18,Apoio!$B$3:$B$81,0)),"")) -> Marcelo Bronzatti | G18: =IF($H18="","",IFERROR(_xlfn.XLOOKUP(H18,'De x Para DRE'!C:C,'De x Para DRE'!B:B),"")) -> 5110100702 | H18: SISTEMAS DE GESTÃO ADM/OPERACIONAL | I18: =IF($G18="","",IFERROR(INDEX('De x Para DRE'!$E$3:$E$210,MATCH($G18,'De x Para DRE'!$B$3:$B$210,0)),"")) -> 3.1 G&A | J18: AKSum IT - Sistema | K18: 495.31 | L18: 495.31 | M18: 495.31 | N18: 495.31 | O18: 495.31 | P18: 495.31 | Q18: 520.0755 | R18: 520.0755 | S18: 520.0755 | T18: 520.0755 | U18: 520.0755 | V18: 520.0755 | W18: =SUM(K18:V18) -> 6092.313 | X18: 495.31 | Y18: 495.31 | Z18: =495.31 -> 495.31 | AA18: 495.31 | AB18: 495.31 | AC18: 495.31 | AD18: 495.31 | AE18: 495.31 | AF18: 495.31 | AG18: 495.31 | AH18: 495.31 | AI18: 495.31 | AJ18: =SUM(X18:AE18) -> 3962.48 | AK18: =SUM(X18:AI18) -> 5943.72 | AL18: 0 | AM18: 0 | AN18: 0 | AO18: 0 | AP18: 0 | AQ18: 0 | AR18: 0 | AS18: 0 | AT18: 0 | AU18: 0 | AV18: 0 | AW18: 0 | AX18: =IF(COUNT($AL18:$AW18)=0,"",SUM($AL18:$AW18)) -> 0 | AY18: =IF($AX18="","",$AX18-IF($W18="",0,$W18)) -> -6092.313 | AZ18: =IF($AX18="","",$AX18-IF($AK18="",0,$AK18)) -> -5943.72 | BA18: R$ 836,64 + O365 [101 usu *148,71] | BB18: Rascunho
A19: =IF(OR($B19="",$D19="",$G19=""),"",ROW()-7) -> 12 | B19: ECEL COMERCIALIZADORA | C19: =IF($B19="","",IFERROR(INDEX(Apoio!$L$3:$L$81,MATCH($B19,Apoio!$K$3:$K$81,0)),"")) -> COMERCIALIZADORA | D19: C104 | E19: =IF($D19="","",IFERROR(INDEX(Apoio!$C$3:$C$81,MATCH($D19,Apoio!$B$3:$B$81,0)),"")) -> TI | F19: =IF($D19="","",IFERROR(INDEX(Apoio!$D$3:$D$81,MATCH($D19,Apoio!$B$3:$B$81,0)),"")) -> Marcelo Bronzatti | G19: =IF($H19="","",IFERROR(_xlfn.XLOOKUP(H19,'De x Para DRE'!C:C,'De x Para DRE'!B:B),"")) -> 5110100702 | H19: SISTEMAS DE GESTÃO ADM/OPERACIONAL | I19: =IF($G19="","",IFERROR(INDEX('De x Para DRE'!$E$3:$E$210,MATCH($G19,'De x Para DRE'!$B$3:$B$210,0)),"")) -> 3.1 G&A | J19: Imagine - Sistema Portal de Compras | W19: =SUM(K19:V19) -> 0 | AB19: 3800 | AC19: =2500+1300 -> 3800 | AD19: 3800 | AE19: 3800 | AF19: 3800 | AG19: 3800 | AH19: 3800 | AI19: 3800 | AJ19: =SUM(X19:AE19) -> 15200 | AK19: =SUM(X19:AI19) -> 30400 | AL19: 1300 | AM19: 1300 | AN19: 1300 | AO19: 1300 | AP19: 1500 | AQ19: 1500 | AR19: 1500 | AS19: 1500 | AT19: 1500 | AU19: 1500 | AV19: 1500 | AW19: 1500 | AX19: =IF(COUNT($AL19:$AW19)=0,"",SUM($AL19:$AW19)) -> 17200 | AY19: =IF($AX19="","",$AX19-IF($W19="",0,$W19)) -> 17200 | AZ19: =IF($AX19="","",$AX19-IF($AK19="",0,$AK19)) -> -13200 | BA19: REAJUSTE IGPM | BB19: Rascunho
A20: =IF(OR($B20="",$D20="",$G20=""),"",ROW()-7) -> 13 | B20: ECEL COMERCIALIZADORA | C20: =IF($B20="","",IFERROR(INDEX(Apoio!$L$3:$L$81,MATCH($B20,Apoio!$K$3:$K$81,0)),"")) -> COMERCIALIZADORA | D20: C104 | E20: =IF($D20="","",IFERROR(INDEX(Apoio!$C$3:$C$81,MATCH($D20,Apoio!$B$3:$B$81,0)),"")) -> TI | F20: =IF($D20="","",IFERROR(INDEX(Apoio!$D$3:$D$81,MATCH($D20,Apoio!$B$3:$B$81,0)),"")) -> Marcelo Bronzatti | G20: =IF($H20="","",IFERROR(_xlfn.XLOOKUP(H20,'De x Para DRE'!C:C,'De x Para DRE'!B:B),"")) -> 5110100702 | H20: SISTEMAS DE GESTÃO ADM/OPERACIONAL | I20: =IF($G20="","",IFERROR(INDEX('De x Para DRE'!$E$3:$E$210,MATCH($G20,'De x Para DRE'!$B$3:$B$210,0)),"")) -> 3.1 G&A | J20: SouCloud - Licenças Office | K20: 21967.74 | L20: 21967.74 | M20: 21967.74 | N20: 21967.74 | O20: 21967.74 | P20: 19967.74 | Q20: 19967.74 | R20: 19967.74 | S20: 19967.74 | T20: 17600 | U20: 17600 | V20: 17600 | W20: =SUM(K20:V20) -> 242509.66 | X20: 21967.74 | Y20: 21967.74 | Z20: 21967.74 | AA20: 21967.74 | AB20: 21967.74 | AC20: 21967.74 | AD20: 21967.74 | AE20: 22020.29 | AF20: 22020.29 | AG20: 22020.29 | AH20: 22020.29 | AI20: 22020.29 | AJ20: =SUM(X20:AE20) -> 175794.47 | AK20: =SUM(X20:AI20) -> 263875.63 | AL20: 16000 | AM20: 16000 | AN20: 16000 | AO20: 16000 | AP20: 16000 | AQ20: 16000 | AR20: 16000 | AS20: 16000 | AT20: 16000 | AU20: 18000 | AV20: 18000 | AW20: 18000 | AX20: =IF(COUNT($AL20:$AW20)=0,"",SUM($AL20:$AW20)) -> 198000 | AY20: =IF($AX20="","",$AX20-IF($W20="",0,$W20)) -> -44509.66 | AZ20: =IF($AX20="","",$AX20-IF($AK20="",0,$AK20)) -> -65875.63 | BA20: SUBS MENSAL S/FIDELIDADE | BB20: Rascunho
A21: =IF(OR($B21="",$D21="",$G21=""),"",ROW()-7) -> 14 | B21: ECEL COMERCIALIZADORA | C21: =IF($B21="","",IFERROR(INDEX(Apoio!$L$3:$L$81,MATCH($B21,Apoio!$K$3:$K$81,0)),"")) -> COMERCIALIZADORA | D21: C104 | E21: =IF($D21="","",IFERROR(INDEX(Apoio!$C$3:$C$81,MATCH($D21,Apoio!$B$3:$B$81,0)),"")) -> TI | F21: =IF($D21="","",IFERROR(INDEX(Apoio!$D$3:$D$81,MATCH($D21,Apoio!$B$3:$B$81,0)),"")) -> Marcelo Bronzatti | G21: =IF($H21="","",IFERROR(_xlfn.XLOOKUP(H21,'De x Para DRE'!C:C,'De x Para DRE'!B:B),"")) -> 5110100702 | H21: SISTEMAS DE GESTÃO ADM/OPERACIONAL | I21: =IF($G21="","",IFERROR(INDEX('De x Para DRE'!$E$3:$E$210,MATCH($G21,'De x Para DRE'!$B$3:$B$210,0)),"")) -> 3.1 G&A | J21: TiqueTaque - Sistema Ponto RH | K21: 605 | L21: 605 | M21: 605 | N21: 605 | O21: 605 | P21: 605 | Q21: 605 | R21: 605 | S21: 605 | T21: 605 | U21: 605 | V21: 605 | W21: =SUM(K21:V21) -> 7260 | Y21: 605.33 | Z21: 605.33 | AA21: 432.59 | AB21: 432.59 | AC21: 432.59 | AD21: 432.59 | AE21: 432.59 | AF21: 432.59 | AG21: 432.59 | AH21: 432.59 | AI21: 432.59 | AJ21: =SUM(X21:AE21) -> 3373.61 | AK21: =SUM(X21:AI21) -> 5103.97 | AL21: 500 | AM21: 500 | AN21: 500 | AO21: 500 | AP21: 500 | AQ21: 500 | AR21: 500 | AS21: 500 | AT21: 500 | AU21: 500 | AV21: 500 | AW21: 500 | AX21: =IF(COUNT($AL21:$AW21)=0,"",SUM($AL21:$AW21)) -> 6000 | AY21: =IF($AX21="","",$AX21-IF($W21="",0,$W21)) -> -1260 | AZ21: =IF($AX21="","",$AX21-IF($AK21="",0,$AK21)) -> 896.03 | BB21: Rascunho
A22: =IF(OR($B22="",$D22="",$G22=""),"",ROW()-7) -> 15 | B22: ECEL COMERCIALIZADORA | C22: =IF($B22="","",IFERROR(INDEX(Apoio!$L$3:$L$81,MATCH($B22,Apoio!$K$3:$K$81,0)),"")) -> COMERCIALIZADORA | D22: C104 | E22: =IF($D22="","",IFERROR(INDEX(Apoio!$C$3:$C$81,MATCH($D22,Apoio!$B$3:$B$81,0)),"")) -> TI | F22: =IF($D22="","",IFERROR(INDEX(Apoio!$D$3:$D$81,MATCH($D22,Apoio!$B$3:$B$81,0)),"")) -> Marcelo Bronzatti | G22: =IF($H22="","",IFERROR(_xlfn.XLOOKUP(H22,'De x Para DRE'!C:C,'De x Para DRE'!B:B),"")) -> 5110100702 | H22: SISTEMAS DE GESTÃO ADM/OPERACIONAL | I22: =IF($G22="","",IFERROR(INDEX('De x Para DRE'!$E$3:$E$210,MATCH($G22,'De x Para DRE'!$B$3:$B$210,0)),"")) -> 3.1 G&A | J22: Infinity Soluções - Sistema 4Expenses | W22: =SUM(K22:V22) -> 0 | AB22: 1800 | AC22: =1800+2500.2 -> 4300.2 | AD22: =1800+2500.2 -> 4300.2 | AE22: 0 | AF22: 0 | AG22: 0 | AH22: 0 | AI22: 0 | AJ22: =SUM(X22:AE22) -> 10400.4 | AK22: =SUM(X22:AI22) -> 10400.4 | AL22: 0 | AM22: 0 | AN22: 0 | AO22: 0 | AP22: 0 | AQ22: 0 | AR22: 0 | AS22: 0 | AT22: 0 | AU22: 0 | AV22: 0 | AW22: 0 | AX22: =IF(COUNT($AL22:$AW22)=0,"",SUM($AL22:$AW22)) -> 0 | AY22: =IF($AX22="","",$AX22-IF($W22="",0,$W22)) -> 0 | AZ22: =IF($AX22="","",$AX22-IF($AK22="",0,$AK22)) -> -10400.4 | BB22: Rascunho
A23: =IF(OR($B23="",$D23="",$G23=""),"",ROW()-7) -> 16 | B23: ECEL COMERCIALIZADORA | C23: =IF($B23="","",IFERROR(INDEX(Apoio!$L$3:$L$81,MATCH($B23,Apoio!$K$3:$K$81,0)),"")) -> COMERCIALIZADORA | D23: C104 | E23: =IF($D23="","",IFERROR(INDEX(Apoio!$C$3:$C$81,MATCH($D23,Apoio!$B$3:$B$81,0)),"")) -> TI | F23: =IF($D23="","",IFERROR(INDEX(Apoio!$D$3:$D$81,MATCH($D23,Apoio!$B$3:$B$81,0)),"")) -> Marcelo Bronzatti | G23: =IF($H23="","",IFERROR(_xlfn.XLOOKUP(H23,'De x Para DRE'!C:C,'De x Para DRE'!B:B),"")) -> 5110100704 | H23: DESPESA TELEFONIA FIXA E MÓVEL | I23: =IF($G23="","",IFERROR(INDEX('De x Para DRE'!$E$3:$E$210,MATCH($G23,'De x Para DRE'!$B$3:$B$210,0)),"")) -> 3.1 G&A | J23: Signallink (SUBS POR SURFIX) | K23: 350 | L23: 350 | M23: 350 | N23: 350 | O23: 350 | P23: 350 | Q23: 367.5 | R23: 367.5 | S23: 367.5 | T23: 367.5 | U23: 367.5 | V23: 367.5 | W23: =SUM(K23:V23) -> 4305 | X23: 321.6 | Y23: 328.35 | Z23: 321.6 | AA23: 328.14 | AB23: =321.6 -> 321.6 | AC23: 321.6 | AD23: 396.6 | AE23: 357.14833 | AF23: 357.14833 | AG23: 357.14833 | AH23: 357.14833 | AI23: 357.14833 | AJ23: =SUM(X23:AE23) -> 2696.6383 | AK23: =SUM(X23:AI23) -> 4125.2317 | AL23: 0 | AM23: 0 | AN23: 0 | AO23: 0 | AP23: 0 | AQ23: 0 | AR23: 0 | AS23: 0 | AT23: 0 | AU23: 0 | AV23: 0 | AW23: 0 | AX23: =IF(COUNT($AL23:$AW23)=0,"",SUM($AL23:$AW23)) -> 0 | AY23: =IF($AX23="","",$AX23-IF($W23="",0,$W23)) -> -4305 | AZ23: =IF($AX23="","",$AX23-IF($AK23="",0,$AK23)) -> -4125.2317 | BB23: Rascunho
A24: =IF(OR($B24="",$D24="",$G24=""),"",ROW()-7) -> 17 | B24: ECEL COMERCIALIZADORA | C24: =IF($B24="","",IFERROR(INDEX(Apoio!$L$3:$L$81,MATCH($B24,Apoio!$K$3:$K$81,0)),"")) -> COMERCIALIZADORA | D24: C104 | E24: =IF($D24="","",IFERROR(INDEX(Apoio!$C$3:$C$81,MATCH($D24,Apoio!$B$3:$B$81,0)),"")) -> TI | F24: =IF($D24="","",IFERROR(INDEX(Apoio!$D$3:$D$81,MATCH($D24,Apoio!$B$3:$B$81,0)),"")) -> Marcelo Bronzatti | G24: =IF($H24="","",IFERROR(_xlfn.XLOOKUP(H24,'De x Para DRE'!C:C,'De x Para DRE'!B:B),"")) -> 5110100704 | H24: DESPESA TELEFONIA FIXA E MÓVEL | I24: =IF($G24="","",IFERROR(INDEX('De x Para DRE'!$E$3:$E$210,MATCH($G24,'De x Para DRE'!$B$3:$B$210,0)),"")) -> 3.1 G&A | J24: TIM - Celulares Corporativos / ( SUBST VIVO CELULAR) | K24: 6600 | L24: 6600 | M24: 7500 | N24: 5000 | O24: 5000 | P24: 5000 | Q24: 5000 | R24: 5000 | S24: 5000 | T24: 5000 | U24: 5000 | V24: 5000 | W24: =SUM(K24:V24) -> 65700 | X24: 6279.47 | Y24: =6380.8-566.99 -> 5813.81 | Z24: 6466.62 | AA24: 3878.18 | AB24: 3759.55 | AC24: 3762.99 | AD24: 4131.83 | AE24: 4311.4 | AF24: 3800.24 | AG24: 3800.24 | AH24: 3800.24 | AI24: 3800.24 | AJ24: =SUM(X24:AE24) -> 38403.85 | AK24: =SUM(X24:AI24) -> 53604.81 | AL24: 3400 | AM24: 3400 | AN24: 3400 | AO24: 3400 | AP24: 3400 | AQ24: 3400 | AR24: 3400 | AS24: 3400 | AT24: 3400 | AU24: 3400 | AV24: 3400 | AW24: 3400 | AX24: =IF(COUNT($AL24:$AW24)=0,"",SUM($AL24:$AW24)) -> 40800 | AY24: =IF($AX24="","",$AX24-IF($W24="",0,$W24)) -> -24900 | AZ24: =IF($AX24="","",$AX24-IF($AK24="",0,$AK24)) -> -12804.81 | BA24: 69 LINHAS * 49,00 | BB24: Rascunho
A25: =IF(OR($B25="",$D25="",$G25=""),"",ROW()-7) -> 18 | B25: ECEL COMERCIALIZADORA | C25: =IF($B25="","",IFERROR(INDEX(Apoio!$L$3:$L$81,MATCH($B25,Apoio!$K$3:$K$81,0)),"")) -> COMERCIALIZADORA | D25: C104 | E25: =IF($D25="","",IFERROR(INDEX(Apoio!$C$3:$C$81,MATCH($D25,Apoio!$B$3:$B$81,0)),"")) -> TI | F25: =IF($D25="","",IFERROR(INDEX(Apoio!$D$3:$D$81,MATCH($D25,Apoio!$B$3:$B$81,0)),"")) -> Marcelo Bronzatti | G25: =IF($H25="","",IFERROR(_xlfn.XLOOKUP(H25,'De x Para DRE'!C:C,'De x Para DRE'!B:B),"")) -> 5110100704 | H25: DESPESA TELEFONIA FIXA E MÓVEL | I25: =IF($G25="","",IFERROR(INDEX('De x Para DRE'!$E$3:$E$210,MATCH($G25,'De x Para DRE'!$B$3:$B$210,0)),"")) -> 3.1 G&A | J25: VIVO - VOIP / A2M TECNOLOGIA EM INTERNET LTDA (SURFIX) | K25: 2438 | L25: 2438 | M25: 2438 | N25: 2438 | O25: 2438 | P25: 2438 | Q25: 2438 | R25: 2438 | S25: 2438 | T25: 2438 | U25: 1000 | V25: 1000 | W25: =SUM(K25:V25) -> 26380 | X25: 2871.33 | Y25: 2855.78 | Z25: 3599.63 | AA25: 4248.26 | AB25: 3955.2 | AC25: 4811.11 | AD25: =1462.02+975.95 -> 2437.97 | AE25: 3884.79 | AF25: 3723.5517 | AG25: 3723.5517 | AH25: 3723.5517 | AI25: 3723.5517 | AJ25: =SUM(X25:AE25) -> 28664.07 | AK25: =SUM(X25:AI25) -> 43558.277 | AL25: 700 | AM25: 700 | AN25: 700 | AO25: 700 | AP25: 700 | AQ25: 700 | AR25: 730 | AS25: 730 | AT25: 730 | AU25: 730 | AV25: 730 | AW25: 730 | AX25: =IF(COUNT($AL25:$AW25)=0,"",SUM($AL25:$AW25)) -> 8580 | AY25: =IF($AX25="","",$AX25-IF($W25="",0,$W25)) -> -17800 | AZ25: =IF($AX25="","",$AX25-IF($AK25="",0,$AK25)) -> -34978.277 | BA25: 15 LINHAS - SERVICO DE TELEFONIA DID 1 CANAL - R$ 15,00 - TOTAL R$ 225,00 01 CENTRAL DE COMUNICAÇÃO CLOUD PABX/IP COM 4 CANAIS SIMULTÂNEOS - R$ 439,00 | BB25: Rascunho
A26: =IF(OR($B26="",$D26="",$G26=""),"",ROW()-7) -> 19 | B26: ECEL COMERCIALIZADORA | C26: =IF($B26="","",IFERROR(INDEX(Apoio!$L$3:$L$81,MATCH($B26,Apoio!$K$3:$K$81,0)),"")) -> COMERCIALIZADORA | D26: C104 | E26: =IF($D26="","",IFERROR(INDEX(Apoio!$C$3:$C$81,MATCH($D26,Apoio!$B$3:$B$81,0)),"")) -> TI | F26: =IF($D26="","",IFERROR(INDEX(Apoio!$D$3:$D$81,MATCH($D26,Apoio!$B$3:$B$81,0)),"")) -> Marcelo Bronzatti | G26: =IF($H26="","",IFERROR(_xlfn.XLOOKUP(H26,'De x Para DRE'!C:C,'De x Para DRE'!B:B),"")) -> 5110100705 | H26: DESPESA COMUNICAÇÃO DE DADOS | I26: =IF($G26="","",IFERROR(INDEX('De x Para DRE'!$E$3:$E$210,MATCH($G26,'De x Para DRE'!$B$3:$B$210,0)),"")) -> 3.1 G&A | J26: CLARO - Redundância Internet Recife | K26: 176 | L26: 176 | M26: 176 | N26: 176 | O26: 200 | P26: 200 | Q26: 200 | R26: 200 | S26: 200 | T26: 200 | U26: 200 | V26: 200 | W26: =SUM(K26:V26) -> 2304 | X26: 146.78 | Y26: 192.63 | Z26: 189.59 | AA26: 189.59 | AB26: 189.59 | AC26: 189.59 | AD26: 189.59 | AE26: 189.59 | AF26: 189.59 | AG26: 189.59 | AH26: 189.59 | AI26: 189.59 | AJ26: =SUM(X26:AE26) -> 1476.95 | AK26: =SUM(X26:AI26) -> 2235.31 | AL26: 200 | AM26: 200 | AN26: 200 | AO26: 200 | AP26: 200 | AQ26: 200 | AR26: 200 | AS26: 200 | AT26: 200 | AU26: 200 | AV26: 200 | AW26: 200 | AX26: =IF(COUNT($AL26:$AW26)=0,"",SUM($AL26:$AW26)) -> 2400 | AY26: =IF($AX26="","",$AX26-IF($W26="",0,$W26)) -> 96 | AZ26: =IF($AX26="","",$AX26-IF($AK26="",0,$AK26)) -> 164.69 | BB26: Rascunho
A27: =IF(OR($B27="",$D27="",$G27=""),"",ROW()-7) -> 20 | B27: ECEL COMERCIALIZADORA | C27: =IF($B27="","",IFERROR(INDEX(Apoio!$L$3:$L$81,MATCH($B27,Apoio!$K$3:$K$81,0)),"")) -> COMERCIALIZADORA | D27: C104 | E27: =IF($D27="","",IFERROR(INDEX(Apoio!$C$3:$C$81,MATCH($D27,Apoio!$B$3:$B$81,0)),"")) -> TI | F27: =IF($D27="","",IFERROR(INDEX(Apoio!$D$3:$D$81,MATCH($D27,Apoio!$B$3:$B$81,0)),"")) -> Marcelo Bronzatti | G27: =IF($H27="","",IFERROR(_xlfn.XLOOKUP(H27,'De x Para DRE'!C:C,'De x Para DRE'!B:B),"")) -> 5110100705 | H27: DESPESA COMUNICAÇÃO DE DADOS | I27: =IF($G27="","",IFERROR(INDEX('De x Para DRE'!$E$3:$E$210,MATCH($G27,'De x Para DRE'!$B$3:$B$210,0)),"")) -> 3.1 G&A | J27: WRL Connect | W27: =SUM(K27:V27) -> 0 | X27: =1201.43+1241.48 -> 2442.91 | Y27: =1241.48*2 -> 2482.96 | AD27: 0 | AE27: 0 | AF27: 0 | AG27: 0 | AH27: 0 | AI27: 0 | AJ27: =SUM(X27:AE27) -> 4925.87 | AK27: =SUM(X27:AI27) -> 4925.87 | AL27: 0 | AM27: 0 | AN27: 0 | AO27: 0 | AP27: 0 | AQ27: 0 | AR27: 0 | AS27: 0 | AT27: 0 | AU27: 0 | AV27: 0 | AW27: 0 | AX27: =IF(COUNT($AL27:$AW27)=0,"",SUM($AL27:$AW27)) -> 0 | AY27: =IF($AX27="","",$AX27-IF($W27="",0,$W27)) -> 0 | AZ27: =IF($AX27="","",$AX27-IF($AK27="",0,$AK27)) -> -4925.87 | BB27: Rascunho
A28: =IF(OR($B28="",$D28="",$G28=""),"",ROW()-7) -> 21 | B28: ECEL COMERCIALIZADORA | C28: =IF($B28="","",IFERROR(INDEX(Apoio!$L$3:$L$81,MATCH($B28,Apoio!$K$3:$K$81,0)),"")) -> COMERCIALIZADORA | D28: C104 | E28: =IF($D28="","",IFERROR(INDEX(Apoio!$C$3:$C$81,MATCH($D28,Apoio!$B$3:$B$81,0)),"")) -> TI | F28: =IF($D28="","",IFERROR(INDEX(Apoio!$D$3:$D$81,MATCH($D28,Apoio!$B$3:$B$81,0)),"")) -> Marcelo Bronzatti | G28: =IF($H28="","",IFERROR(_xlfn.XLOOKUP(H28,'De x Para DRE'!C:C,'De x Para DRE'!B:B),"")) -> 5110100705 | H28: DESPESA COMUNICAÇÃO DE DADOS | I28: =IF($G28="","",IFERROR(INDEX('De x Para DRE'!$E$3:$E$210,MATCH($G28,'De x Para DRE'!$B$3:$B$210,0)),"")) -> 3.1 G&A | J28: CLDS Cloud/Mundivox - Internet Recife | K28: 2750 | L28: 2750 | M28: 2750 | N28: 2750 | O28: 2750 | P28: 2750 | Q28: 2750 | R28: 2750 | S28: 2750 | T28: 2750 | U28: 2750 | V28: 2750 | W28: =SUM(K28:V28) -> 33000 | X28: 1201.43 | Y28: =1500+1480.5 -> 2980.5 | Z28: =680.81+1241.48+1500 -> 3422.29 | AA28: 2741.48 | AB28: 2741.48 | AC28: 2741.48 | AD28: 2741.48 | AE28: 2741.48 | AF28: 2741.48 | AG28: 2741.48 | AH28: 2741.48 | AI28: 2741.48 | AJ28: =SUM(X28:AE28) -> 21311.62 | AK28: =SUM(X28:AI28) -> 32277.54 | AL28: 2741 | AM28: 2741 | AN28: 2741 | AO28: 2741 | AP28: 2741 | AQ28: 2741 | AR28: 2741 | AS28: 2741 | AT28: 2741 | AU28: 2741 | AV28: 2741 | AW28: 2741 | AX28: =IF(COUNT($AL28:$AW28)=0,"",SUM($AL28:$AW28)) -> 32892 | AY28: =IF($AX28="","",$AX28-IF($W28="",0,$W28)) -> -108 | AZ28: =IF($AX28="","",$AX28-IF($AK28="",0,$AK28)) -> 614.46 | BB28: Rascunho
A29: =IF(OR($B29="",$D29="",$G29=""),"",ROW()-7) -> 22 | B29: ECEL COMERCIALIZADORA | C29: =IF($B29="","",IFERROR(INDEX(Apoio!$L$3:$L$81,MATCH($B29,Apoio!$K$3:$K$81,0)),"")) -> COMERCIALIZADORA | D29: C104 | E29: =IF($D29="","",IFERROR(INDEX(Apoio!$C$3:$C$81,MATCH($D29,Apoio!$B$3:$B$81,0)),"")) -> TI | F29: =IF($D29="","",IFERROR(INDEX(Apoio!$D$3:$D$81,MATCH($D29,Apoio!$B$3:$B$81,0)),"")) -> Marcelo Bronzatti | G29: =IF($H29="","",IFERROR(_xlfn.XLOOKUP(H29,'De x Para DRE'!C:C,'De x Para DRE'!B:B),"")) -> 5110100705 | H29: DESPESA COMUNICAÇÃO DE DADOS | I29: =IF($G29="","",IFERROR(INDEX('De x Para DRE'!$E$3:$E$210,MATCH($G29,'De x Para DRE'!$B$3:$B$210,0)),"")) -> 3.1 G&A | J29: SantoDigital - Google | K29: 60 | L29: 60 | M29: 60 | N29: 60 | O29: 400 | P29: 400 | Q29: 400 | R29: 400 | S29: 400 | T29: 400 | U29: 400 | V29: 400 | W29: =SUM(K29:V29) -> 3440 | X29: 54.39 | Y29: 66.75 | Z29: 35.41 | AA29: 37.01 | AB29: =357.42 -> 357.42 | AC29: =359.48 -> 359.48 | AD29: 489.36 | AE29: 743.5 | AF29: 359.48 | AG29: 359.48 | AH29: 359.48 | AI29: 359.48 | AJ29: =SUM(X29:AE29) -> 2143.32 | AK29: =SUM(X29:AI29) -> 3581.24 | AL29: 1500 | AM29: 1500 | AN29: 1500 | AO29: 1500 | AP29: 1500 | AQ29: 1500 | AR29: 1500 | AS29: 1500 | AT29: 1500 | AU29: 1500 | AV29: 1500 | AW29: 1500 | AX29: =IF(COUNT($AL29:$AW29)=0,"",SUM($AL29:$AW29)) -> 18000 | AY29: =IF($AX29="","",$AX29-IF($W29="",0,$W29)) -> 14560 | AZ29: =IF($AX29="","",$AX29-IF($AK29="",0,$AK29)) -> 14418.76 | BB29: Rascunho
A30: =IF(OR($B30="",$D30="",$G30=""),"",ROW()-7) -> 23 | B30: ECEL COMERCIALIZADORA | C30: =IF($B30="","",IFERROR(INDEX(Apoio!$L$3:$L$81,MATCH($B30,Apoio!$K$3:$K$81,0)),"")) -> COMERCIALIZADORA | D30: C104 | E30: =IF($D30="","",IFERROR(INDEX(Apoio!$C$3:$C$81,MATCH($D30,Apoio!$B$3:$B$81,0)),"")) -> TI | F30: =IF($D30="","",IFERROR(INDEX(Apoio!$D$3:$D$81,MATCH($D30,Apoio!$B$3:$B$81,0)),"")) -> Marcelo Bronzatti | G30: =IF($H30="","",IFERROR(_xlfn.XLOOKUP(H30,'De x Para DRE'!C:C,'De x Para DRE'!B:B),"")) -> 5110100803 | H30: DESPESA COM HOSPEDAGEM | I30: =IF($G30="","",IFERROR(INDEX('De x Para DRE'!$E$3:$E$210,MATCH($G30,'De x Para DRE'!$B$3:$B$210,0)),"")) -> 3.1 G&A | J30: Hospedagens | K30: 240.73875 | L30: 240.73875 | M30: 240.73875 | N30: 240.73875 | O30: 240.73875 | P30: 240.73875 | Q30: 240.73875 | R30: 240.73875 | S30: 240.73875 | T30: 240.73875 | U30: 240.73875 | V30: 240.73875 | W30: =SUM(K30:V30) -> 2888.865 | X30: 0 | Y30: 1116.15 | Z30: 2370.4 | AA30: 0 | AB30: 0 | AC30: 0 | AD30: 0 | AE30: 0 | AF30: 0 | AG30: 0 | AH30: 0 | AI30: 0 | AJ30: =SUM(X30:AE30) -> 3486.55 | AK30: =SUM(X30:AI30) -> 3486.55 | AL30: 500 | AM30: 500 | AN30: 500 | AO30: 500 | AP30: 500 | AQ30: 500 | AR30: 500 | AS30: 500 | AT30: 500 | AU30: 500 | AV30: 500 | AW30: 500 | AX30: =IF(COUNT($AL30:$AW30)=0,"",SUM($AL30:$AW30)) -> 6000 | AY30: =IF($AX30="","",$AX30-IF($W30="",0,$W30)) -> 3111.135 | AZ30: =IF($AX30="","",$AX30-IF($AK30="",0,$AK30)) -> 2513.45 | BB30: Rascunho
A31: =IF(OR($B31="",$D31="",$G31=""),"",ROW()-7) -> 24 | B31: ECEL COMERCIALIZADORA | C31: =IF($B31="","",IFERROR(INDEX(Apoio!$L$3:$L$81,MATCH($B31,Apoio!$K$3:$K$81,0)),"")) -> COMERCIALIZADORA | D31: C104 | E31: =IF($D31="","",IFERROR(INDEX(Apoio!$C$3:$C$81,MATCH($D31,Apoio!$B$3:$B$81,0)),"")) -> TI | F31: =IF($D31="","",IFERROR(INDEX(Apoio!$D$3:$D$81,MATCH($D31,Apoio!$B$3:$B$81,0)),"")) -> Marcelo Bronzatti | G31: =IF($H31="","",IFERROR(_xlfn.XLOOKUP(H31,'De x Para DRE'!C:C,'De x Para DRE'!B:B),"")) -> 5110100804 | H31: DESPESA COM PASSAGENS | I31: =IF($G31="","",IFERROR(INDEX('De x Para DRE'!$E$3:$E$210,MATCH($G31,'De x Para DRE'!$B$3:$B$210,0)),"")) -> 3.1 G&A | J31: Passagens | K31: 737.79 | L31: 737.79 | M31: 737.79 | N31: 737.79 | O31: 737.79 | P31: 737.79 | Q31: 737.79 | R31: 737.79 | S31: 737.79 | T31: 737.79 | U31: 737.79 | V31: 737.79 | W31: =SUM(K31:V31) -> 8853.48 | X31: 2923.11 | Y31: 1418.42 | Z31: 3915.02 | AA31: 0 | AB31: 0 | AC31: 0 | AD31: 0 | AE31: 0 | AF31: 0 | AG31: 0 | AH31: 0 | AI31: 0 | AJ31: =SUM(X31:AE31) -> 8256.55 | AK31: =SUM(X31:AI31) -> 8256.55 | AL31: 600 | AM31: 600 | AN31: 600 | AO31: 600 | AP31: 600 | AQ31: 600 | AR31: 600 | AS31: 600 | AT31: 600 | AU31: 600 | AV31: 600 | AW31: 600 | AX31: =IF(COUNT($AL31:$AW31)=0,"",SUM($AL31:$AW31)) -> 7200 | AY31: =IF($AX31="","",$AX31-IF($W31="",0,$W31)) -> -1653.48 | AZ31: =IF($AX31="","",$AX31-IF($AK31="",0,$AK31)) -> -1056.55 | BB31: Rascunho
A32: =IF(OR($B32="",$D32="",$G32=""),"",ROW()-7) -> 25 | B32: ECEL COMERCIALIZADORA | C32: =IF($B32="","",IFERROR(INDEX(Apoio!$L$3:$L$81,MATCH($B32,Apoio!$K$3:$K$81,0)),"")) -> COMERCIALIZADORA | D32: C104 | E32: =IF($D32="","",IFERROR(INDEX(Apoio!$C$3:$C$81,MATCH($D32,Apoio!$B$3:$B$81,0)),"")) -> TI | F32: =IF($D32="","",IFERROR(INDEX(Apoio!$D$3:$D$81,MATCH($D32,Apoio!$B$3:$B$81,0)),"")) -> Marcelo Bronzatti | G32: =IF($H32="","",IFERROR(_xlfn.XLOOKUP(H32,'De x Para DRE'!C:C,'De x Para DRE'!B:B),"")) -> 5110100917 | H32: DESPESA COMBUST./LUBRIF. VEÍCULOS | I32: =IF($G32="","",IFERROR(INDEX('De x Para DRE'!$E$3:$E$210,MATCH($G32,'De x Para DRE'!$B$3:$B$210,0)),"")) -> 3.1 G&A | J32: Combustível | W32: =SUM(K32:V32) -> 0 | Z32: 642.5 | AD32: 0 | AE32: 0 | AF32: 0 | AG32: 0 | AH32: 0 | AI32: 0 | AJ32: =SUM(X32:AE32) -> 642.5 | AK32: =SUM(X32:AI32) -> 642.5 | AL32: 0 | AM32: 0 | AN32: 0 | AO32: 0 | AP32: 0 | AQ32: 0 | AR32: 0 | AS32: 0 | AT32: 0 | AU32: 0 | AV32: 0 | AW32: 0 | AX32: =IF(COUNT($AL32:$AW32)=0,"",SUM($AL32:$AW32)) -> 0 | AY32: =IF($AX32="","",$AX32-IF($W32="",0,$W32)) -> 0 | AZ32: =IF($AX32="","",$AX32-IF($AK32="",0,$AK32)) -> -642.5 | BB32: Rascunho
A33: =IF(OR($B33="",$D33="",$G33=""),"",ROW()-7) -> 26 | B33: ECEL COMERCIALIZADORA | C33: =IF($B33="","",IFERROR(INDEX(Apoio!$L$3:$L$81,MATCH($B33,Apoio!$K$3:$K$81,0)),"")) -> COMERCIALIZADORA | D33: C104 | E33: =IF($D33="","",IFERROR(INDEX(Apoio!$C$3:$C$81,MATCH($D33,Apoio!$B$3:$B$81,0)),"")) -> TI | F33: =IF($D33="","",IFERROR(INDEX(Apoio!$D$3:$D$81,MATCH($D33,Apoio!$B$3:$B$81,0)),"")) -> Marcelo Bronzatti | G33: =IF($H33="","",IFERROR(_xlfn.XLOOKUP(H33,'De x Para DRE'!C:C,'De x Para DRE'!B:B),"")) -> 5110100706 | H33: DESPESA LOCAÇÃO DE IMPRESSORAS | I33: =IF($G33="","",IFERROR(INDEX('De x Para DRE'!$E$3:$E$210,MATCH($G33,'De x Para DRE'!$B$3:$B$210,0)),"")) -> 3.1 G&A | J33: Locação Impressoras / RBS NASCIMENTO | N33: 600 | O33: 600 | P33: 600 | Q33: 600 | R33: 600 | S33: 600 | T33: 600 | U33: 600 | V33: 600 | W33: =SUM(K33:V33) -> 5400 | Z33: 600 | AB33: 600 | AC33: 600 | AD33: 600 | AE33: 600 | AF33: 600 | AG33: 600 | AH33: 600 | AI33: 600 | AJ33: =SUM(X33:AE33) -> 3000 | AK33: =SUM(X33:AI33) -> 5400 | AL33: 600 | AM33: 600 | AN33: 600 | AO33: 600 | AP33: 600 | AQ33: 600 | AR33: 600 | AS33: 600 | AT33: 600 | AU33: 600 | AV33: 600 | AW33: 600 | AX33: =IF(COUNT($AL33:$AW33)=0,"",SUM($AL33:$AW33)) -> 7200 | AY33: =IF($AX33="","",$AX33-IF($W33="",0,$W33)) -> 1800 | AZ33: =IF($AX33="","",$AX33-IF($AK33="",0,$AK33)) -> 1800 | BB33: Rascunho
A34: =IF(OR($B34="",$D34="",$G34=""),"",ROW()-7) -> 27 | B34: ECEL COMERCIALIZADORA | C34: =IF($B34="","",IFERROR(INDEX(Apoio!$L$3:$L$81,MATCH($B34,Apoio!$K$3:$K$81,0)),"")) -> COMERCIALIZADORA | D34: C104 | E34: =IF($D34="","",IFERROR(INDEX(Apoio!$C$3:$C$81,MATCH($D34,Apoio!$B$3:$B$81,0)),"")) -> TI | F34: =IF($D34="","",IFERROR(INDEX(Apoio!$D$3:$D$81,MATCH($D34,Apoio!$B$3:$B$81,0)),"")) -> Marcelo Bronzatti | G34: =IF($H34="","",IFERROR(_xlfn.XLOOKUP(H34,'De x Para DRE'!C:C,'De x Para DRE'!B:B),"")) -> 5110100204 | H34: DESPESA MANUTENÇÃO VEÍCULOS LEVES | I34: =IF($G34="","",IFERROR(INDEX('De x Para DRE'!$E$3:$E$210,MATCH($G34,'De x Para DRE'!$B$3:$B$210,0)),"")) -> 3.1 G&A | J34: Manutenção de Veículos | W34: =SUM(K34:V34) -> 0 | Z34: =647.5*3 -> 1942.5 | AD34: 0 | AE34: 0 | AF34: 0 | AG34: 0 | AH34: 0 | AI34: 0 | AJ34: =SUM(X34:AE34) -> 1942.5 | AK34: =SUM(X34:AI34) -> 1942.5 | AL34: 0 | AM34: 0 | AN34: 0 | AO34: 0 | AP34: 0 | AQ34: 0 | AR34: 0 | AS34: 0 | AT34: 0 | AU34: 0 | AV34: 0 | AW34: 0 | AX34: =IF(COUNT($AL34:$AW34)=0,"",SUM($AL34:$AW34)) -> 0 | AY34: =IF($AX34="","",$AX34-IF($W34="",0,$W34)) -> 0 | AZ34: =IF($AX34="","",$AX34-IF($AK34="",0,$AK34)) -> -1942.5 | BB34: Rascunho
